Workbook

Sheet cached_users
A1: USER_ID | B1: NAME | C1: BIRTHDAY | D1: -
A2: 6IpRbH9XzzcZRKoS1L5Pg3nm7qJ2 | B2: Renato Inzaghi | C2: 25600 | D2: 55
A3: LPrFZqM6IQcAoUSQdWTvLi52Uft1 | B3: C√©dric Lefoul | C3: 25636 | D3: 55
A4: mZu7rd6EfsgW7q37oeZJXiueQKo2 | B4: John Massa | C4: 25720 | D4: 55
A5: n0UShQCahYUfeaPKzDK6YGa6eJD3 | B5: Lenny Desbonnes | C5: 25729 | D5: 55
A6: KM6eaHvVavYE40EcheqPnyDlWtj1 | B6: bernard nguyen vany | C6: 25923 | D6: 54
A7: mnNqLXAGGkhiY32ac8sNlAJ46Ba2 | B7: Thierry Platoche | C7: 25948 | D7: 54
A8: Cb1XwpjGXpXZ4FQS4PGDwqWGZSu1 | B8: Kamel Benyoucef | C8: 25957 | D8: 54
A9: w1Z7XCTucCZEiCJyOLqvqZTYsB83 | B9: Carlos Martins | C9: 25960 | D9: 54
A10: 96GNB0RtsYfCuM4gKA3rp3ZwFTn1 | B10: St√©phane Maddelein (SAM) | C10: 26007 | D10: 54
A11: O6gODFOT2MQJul8DrGKao4tlQsS2 | B11: St√©phane Maddelein | C11: 26007 | D11: 54
A12: pGn4K816l5PnGHgyowHKSiH1ABD3 | B12: patrick viale-civatte | C12: 26067 | D12: 54
A13: HLxCLPCUHMeAJE9SRXfnreRPpL52 | B13: Smail Khermane | C13: 26079 | D13: 54
... A13633: HFHS04Zqu6QdTcWjMuwW6QrhkOj2 | B13633: Adel adel | C13633: 36418 | D13633: 25
A13634: EAcUGLUhmhhGhDvXKMIk5K16HV03 | C13634: 36419 | D13634: 25
A13635: Jbs1kafGUgPBJFAZYOKZG7RJ3gj2 | B13635: Anton Tortel | C13635: 36419 | D13635: 25
A13636: iWbnvTFhzBSeNitBb8TGIoUgMMJ2 | B13636: L√©on Gel | C13636: 36419 | D13636: 25
A13637: BeklREOgLEOovKuGxgBBJGo8hA42 | B13637: Lilian Lacaz | C13637: 36420 | D13637: 25
A13638: Dz9JSDXzBJRPOncM6r0C54FO7FC3 | B13638: Dylan Vassa | C13638: 36420 | D13638: 25
A13639: X1xLBWkeuKZKhkGl53INC3Xzzsk1 | B13639: wassim wassim | C13639: 36420 | D13639: 25
A13640: c0gzoCxQuRZuV7mQ8IJhls5J4ju2 | B13640: MIGUEL Eleuterio | C13640: 36420 | D13640: 25
A13641: 7LykhIDBHGMsXlngPAs4GkYYCEG2 | B13641: Ib Piba | C13641: 36421 | D13641: 25
A13642: EggyKyTZlgTRS0D2TZG1SzINOhE3 | B13642: Marouane Coslo | C13642: 36421 | D13642: 25
A13643: NymTc13A03ZYmY69ZIale27F6mf2 | B13643: Antoine Domin√© | C13643: 36421 | D13643: 25
A13644: 0cqUebSHYxXl8OWZHZftVDZiz8p2 | B13644: Zakaria Mejdoub | C13644: 36422 | D13644: 25
A13645: LvBG47x9gfSmIjG2BbtwUqg8sNp1 | B13645: Abdoulaye Toure | C13645: 36422 | D13645: 25
A13646: V7u2yspG0bee91mNwflk2Q1FgCa2 | B13646: Owen Dixon | C13646: 36422 | D13646: 25
... A18259: fAyU0xhAWmOBGg9c2YrFDIgHPL32 | B18259: Kisoka Mayakameme | C18259: 41503 | D18259: 11

Sheet demographic study june
A1: Age | B1: Users
A2: 11 | B2: =COUNTIFS(cached_users!$D:$D,'demographic study june'!A2) -> 1 | E2: Entre | F2: et
A3: 12 | B3: =COUNTIFS(cached_users!$D:$D,'demographic study june'!A3) -> 1 | E3: 18 | F3: 20 | G3: =SUMIFS($B:$B,$A:$A,">="&E3,$A:$A,"<"&F3) -> 326 | H3: =G3/SUM($G$3:$G$11) -> 0.017950553
A4: 13 | B4: =COUNTIFS(cached_users!$D:$D,'demographic study june'!A4) -> 4 | E4: 20 | F4: 25 | G4: =SUMIFS($B:$B,$A:$A,">="&E4,$A:$A,"<"&F4) -> 3359 | H4: =G4/SUM($G$3:$G$11) -> 0.18495678
A5: 14 | B5: =COUNTIFS(cached_users!$D:$D,'demographic study june'!A5) -> 4 | E5: 25 | F5: 30 | G5: =SUMIFS($B:$B,$A:$A,">="&E5,$A:$A,"<"&F5) -> 5508 | H5: =G5/SUM($G$3:$G$11) -> 0.30328726
A6: 15 | B6: =COUNTIFS(cached_users!$D:$D,'demographic study june'!A6) -> 8 | E6: 30 | F6: 35 | G6: =SUMIFS($B:$B,$A:$A,">="&E6,$A:$A,"<"&F6) -> 4772 | H6: =G6/SUM($G$3:$G$11) -> 0.26276086
A7: 16 | B7: =COUNTIFS(cached_users!$D:$D,'demographic study june'!A7) -> 21 | E7: 35 | F7: 40 | G7: =SUMIFS($B:$B,$A:$A,">="&E7,$A:$A,"<"&F7) -> 2668 | H7: =G7/SUM($G$3:$G$11) -> 0.14690821
A8: 17 | B8: =COUNTIFS(cached_users!$D:$D,'demographic study june'!A8) -> 58 | E8: 40 | F8: 45 | G8: =SUMIFS($B:$B,$A:$A,">="&E8,$A:$A,"<"&F8) -> 1083 | H8: =G8/SUM($G$3:$G$11) -> 0.05963328
A9: 18 | B9: =COUNTIFS(cached_users!$D:$D,'demographic study june'!A9) -> 96 | E9: 45 | F9: 50 | G9: =SUMIFS($B:$B,$A:$A,">="&E9,$A:$A,"<"&F9) -> 345 | H9: =G9/SUM($G$3:$G$11) -> 0.018996751
A10: 19 | B10: =COUNTIFS(cached_users!$D:$D,'demographic study june'!A10) -> 230 | E10: 50 | F10: 55 | G10: =SUMIFS($B:$B,$A:$A,">="&E10,$A:$A,"<"&F10) -> 96 | H10: =G10/SUM($G$3:$G$11) -> 0.0052860525
A11: 20 | B11: =COUNTIFS(cached_users!$D:$D,'demographic study june'!A11) -> 434 | E11: 55 | F11: 60 | G11: =SUMIFS($B:$B,$A:$A,">="&E11,$A:$A,"<"&F11) -> 4 | H11: =G11/SUM($G$3:$G$11) -> 0.00022025219
A12: 21 | B12: =COUNTIFS(cached_users!$D:$D,'demographic study june'!A12) -> 515
A13: 22 | B13: =COUNTIFS(cached_users!$D:$D,'demographic study june'!A13) -> 658
A14: 23 | B14: =COUNTIFS(cached_users!$D:$D,'demographic study june'!A14) -> 813
A15: 24 | B15: =COUNTIFS(cached_users!$D:$D,'demographic study june'!A15) -> 939
A16: 25 | B16: =COUNTIFS(cached_users!$D:$D,'demographic study june'!A16) -> 1097
A17: 26 | B17: =COUNTIFS(cached_users!$D:$D,'demographic study june'!A17) -> 1058 | E17: Entre | F17: et
A18: 27 | B18: =COUNTIFS(cached_users!$D:$D,'demographic study june'!A18) -> 1199 | E18: 18 | F18: 25 | G18: =SUMIFS($B:$B,$A:$A,">="&E18,$A:$A,"<"&F18) -> 3685 | H18: =G18/SUM($G$3:$G$11) -> 0.20290733
A19: 28 | B19: =COUNTIFS(cached_users!$D:$D,'demographic study june'!A19) -> 1028 | E19: 25 | F19: 35 | G19: =SUMIFS($B:$B,$A:$A,">="&E19,$A:$A,"<"&F19) -> 10280 | H19: =G19/SUM($G$3:$G$11) -> 0.56604813
A20: 29 | B20: =COUNTIFS(cached_users!$D:$D,'demographic study june'!A20) -> 1126 | E20: 35 | F20: 50 | G20: =SUMIFS($B:$B,$A:$A,">="&E20,$A:$A,"<"&F20) -> 4096 | H20: =G20/SUM($G$3:$G$11) -> 0.22553824
A21: 30 | B21: =COUNTIFS(cached_users!$D:$D,'demographic study june'!A21) -> 1077 | E21: 50 | F21: 60 | G21: =SUMIFS($B:$B,$A:$A,">="&E21,$A:$A,"<"&F21) -> 100 | H21: =G21/SUM($G$3:$G$11) -> 0.0055063047
A22: 31 | B22: =COUNTIFS(cached_users!$D:$D,'demographic study june'!A22) -> 995
A23: 32 | B23: =COUNTIFS(cached_users!$D:$D,'demographic study june'!A23) -> 958
A24: 33 | B24: =COUNTIFS(cached_users!$D:$D,'demographic study june'!A24) -> 892
A25: 34 | B25: =COUNTIFS(cached_users!$D:$D,'demographic study june'!A25) -> 850
A26: 35 | B26: =COUNTIFS(cached_users!$D:$D,'demographic study june'!A26) -> 746 | E26: Entre | F26: et
A27: 36 | B27: =COUNTIFS(cached_users!$D:$D,'demographic study june'!A27) -> 615 | E27: 18 | F27: 23 | G27: =SUMIFS($B:$B,$A:$A,">="&E27,$A:$A,"<"&F27) -> 1933 | H27: =G27/SUM($G$3:$G$11) -> 0.10643687
A28: 37 | B28: =COUNTIFS(cached_users!$D:$D,'demographic study june'!A28) -> 540 | E28: 23 | F28: 28 | G28: =SUMIFS($B:$B,$A:$A,">="&E28,$A:$A,"<"&F28) -> 5106 | H28: =G28/SUM($G$3:$G$11) -> 0.28115192
A29: 38 | B29: =COUNTIFS(cached_users!$D:$D,'demographic study june'!A29) -> 429 | E29: 28 | F29: 33 | G29: =SUMIFS($B:$B,$A:$A,">="&E29,$A:$A,"<"&F29) -> 5184 | H29: =G29/SUM($G$3:$G$11) -> 0.28544684
A30: 39 | B30: =COUNTIFS(cached_users!$D:$D,'demographic study june'!A30) -> 338 | E30: 33 | F30: 38 | G30: =SUMIFS($B:$B,$A:$A,">="&E30,$A:$A,"<"&F30) -> 3643 | H30: =G30/SUM($G$3:$G$11) -> 0.20059468
A31: 40 | B31: =COUNTIFS(cached_users!$D:$D,'demographic study june'!A31) -> 301 | E31: 38 | F31: 60 | G31: =SUMIFS($B:$B,$A:$A,">="&E31,$A:$A,"<"&F31) -> 2295 | H31: =G31/SUM($G$3:$G$11) -> 0.12636969
A32: 41 | B32: =COUNTIFS(cached_users!$D:$D,'demographic study june'!A32) -> 269
A33: 42 | B33: =COUNTIFS(cached_users!$D:$D,'demographic study june'!A33) -> 192
A34: 43 | B34: =COUNTIFS(cached_users!$D:$D,'demographic study june'!A34) -> 183 | E34: Entre | F34: et
A35: 44 | B35: =COUNTIFS(cached_users!$D:$D,'demographic study june'!A35) -> 138 | E35: 18 | F35: 24 | G35: =SUMIFS($B:$B,$A:$A,">="&E35,$A:$A,"<"&F35) -> 2746 | H35: =G35/SUM($G$3:$G$11) -> 0.15120313
A36: 45 | B36: =COUNTIFS(cached_users!$D:$D,'demographic study june'!A36) -> 104 | E36: 24 | F36: 30 | G36: =SUMIFS($B:$B,$A:$A,">="&E36,$A:$A,"<"&F36) -> 6447 | H36: =G36/SUM($G$3:$G$11) -> 0.35499147
A37: 46 | B37: =COUNTIFS(cached_users!$D:$D,'demographic study june'!A37) -> 73 | E37: 30 | F37: 36 | G37: =SUMIFS($B:$B,$A:$A,">="&E37,$A:$A,"<"&F37) -> 5518 | H37: =G37/SUM($G$3:$G$11) -> 0.30383789
A38: 47 | B38: =COUNTIFS(cached_users!$D:$D,'demographic study june'!A38) -> 76 | E38: 36 | F38: 42 | G38: =SUMIFS($B:$B,$A:$A,">="&E38,$A:$A,"<"&F38) -> 2492 | H38: =G38/SUM($G$3:$G$11) -> 0.13721711
A39: 48 | B39: =COUNTIFS(cached_users!$D:$D,'demographic study june'!A39) -> 55 | E39: 42 | F39: 48 | G39: =SUMIFS($B:$B,$A:$A,">="&E39,$A:$A,"<"&F39) -> 766 | H39: =G39/SUM($G$3:$G$11) -> 0.042178294
A40: 49 | B40: =COUNTIFS(cached_users!$D:$D,'demographic study june'!A40) -> 37 | E40: 48 | F40: 60 | G40: =SUMIFS($B:$B,$A:$A,">="&E40,$A:$A,"<"&F40) -> 192 | H40: =G40/SUM($G$3:$G$11) -> 0.010572105
...
