Workbook

Sheet games
A1: DOC_ID | B1: CENTRE | C1: STATUS | D1: PLACE_ID | E1: LOCATION | F1: DATE
A2: 00D0EPKylfi3bz0wt7ZI | B2: Game 13 foot indoor | C2: canceled | D2: ChIJNSDvlsXryRIRUXao9hwB79I | E2: 43.41258939999999&5.366617 | F2: 2023-10-16T18:30:00.000Z
A3: 00HTbiPPxn91ynn7qR1L | B3: UrbanSoccer - Porte d'Aubervilliers | C3: played | D3: ChIJ0dXjDCZs5kcRvX0EpMwxsUY | E3: 48.9074912&2.3746518 | F3: 2024-01-07T10:00:00.000Z
A4: 00KQmUOvGxj4u2l7AKnP | B4: UrbanSoccer - Lille Lezennes | C4: canceled | E4: 50.6169533&3.0995426 | F4: 2023-09-05T20:00:00.000Z
A5: 00LrLdN1UmDSaFH0PwoM | B5: We Are Sports | C5: canceled | D5: ChIJFZU5oBHC9EcRJTFrSkI1xxg | E5: 45.7113247&4.8761886 | F5: 2023-10-29T09:00:00.000Z
A6: 00NjDYA0rVMKo7x0Z4iR | B6: Footbox | C6: published | D6: ChIJY-WkusIR5kcR-tEad3UtaSQ | E6: 48.9022789&2.582647 | F6: 2024-01-07T17:00:00.000Z
A7: 00eHWDuZqESMgqL1WRhK | B7: UrbanSoccer La D√©fense | C7: draft | D7: ChIJh4rnfVhk5kcRV2Q-ZKdm8vA | E7: 48.8996456&2.2216773 | F7: 2023-12-27T17:45:00.000Z
A8: 00pEnMODhbHxhdN9bcOs | B8: Stadium Thiais | C8: played | E8: 48.7511024&2.3713455 | F8: 2023-10-31T16:30:00.000Z
A9: 00pmhG4IkKds1ZDVdsso | B9: Foot POWER 5 | C9: canceled | E9: 48.960066&2.2061913 | F9: 2024-02-06T17:00:00.000Z
A10: 00zKqorbhZeaIg0UDJDF | B10: Le 13 - Foot en salle - Marseille | C10: canceled | D10: ChIJR62kUm_ByRIRDnGQqGCeUVQ | E10: 43.33370070000001&5.370389599999999 | F10: 2024-01-23T22:15:00.000Z
A11: 01DNdi3KlujTX6skrg3g | B11: Game 13 foot indoor | C11: played | D11: ChIJNSDvlsXryRIRUXao9hwB79I | E11: 43.41258939999999&5.366617 | F11: 2024-01-23T20:30:00.000Z
A12: 01JxNMzkCrf2HKGsi0nV | B12: LE FIVE Carri√®res-sous-Poissy | C12: played | E12: 48.9468144&2.0230574 | F12: 2023-09-08T20:00:00.000Z
A13: 01QB6kfRmLf35vYRDrOE | B13: Stade de foot Pompadour | C13: published | D13: ChIJZWcRAWN15kcR0aRSqeWgmaI | E13: 48.773015&2.432866 | F13: 2024-01-06T11:00:00.000Z
A14: 01ZbJa9fM9COMXnLynCM | B14: LE FIVE Paris 18 | C14: played | D14: ChIJpVT4_n1u5kcRzji6FdTBXXo | E14: 48.8978522&2.3700234 | F14: 2024-01-10T17:30:00.000Z
A15: 01aiIXTWgJgnxa4xFnIt | B15: LE FIVE Paris 17 | C15: played | E15: 48.900032&2.3213449 | F15: 2023-09-02T15:00:00.000Z
A16: 01fMyFWQrEhSbW2upztG | B16: Stadium Thiais | C16: draft | D16: ChIJ64X9jzx05kcRsHvSfOv6UcA | E16: 48.7511024&2.3713455 | F16: 2023-12-02T16:00:00.000Z
A17: 029oObNC5LKinw1cS1l2 | B17: UrbanSoccer - Marne-La-Vall√©e | C17: draft | D17: ChIJ6bDBiosP5kcROXiloHzSdhc | E17: 48.82658600000001&2.6296937
A18: 02P4Ad46JMOKQr3nHXVI | B18: LE FIVE Montreuil | C18: published | E18: 48.8613036&2.4653095 | F18: 2024-02-27T09:00:00.000Z
A19: 02VDY3BeIYvvYul4Tl3O | B19: UrbanSoccer - Puteaux | C19: played | D19: ChIJM_sC0-Nk5kcRhL1y_EFIje8 | E19: 48.8836397&2.2312283 | F19: 2023-11-04T12:30:00.000Z
A20: 02VdYJG2vTOPskH6b3Ap | B20: LE FIVE Marville - La Courneuve | C20: published | E20: 48.9361223&2.3872592 | F20: 2023-10-03T12:00:00.000Z
A21: 02WXbhGT2w7FtZZbdOEJ | B21: UrbanSoccer - Puteaux | C21: canceled | E21: 48.8836397&2.2312283 | F21: 2023-09-22T18:00:00.000Z
A22: 02h87XMAB9N8Lny6HT0I | B22: UrbanSoccer - Puteaux | C22: canceled | D22: ChIJM_sC0-Nk5kcRhL1y_EFIje8 | E22: 48.8836397&2.2312283 | F22: 2023-10-20T17:15:00.000Z
A23: 02lQ08jQ1qczkosCpNjh | B23: UrbanSoccer - Porte d'Aubervilliers | C23: played | E23: 48.9074912&2.3746518 | F23: 2023-09-10T15:30:00.000Z
A24: 02oe8khjbfJUb1QNXSTN | B24: UrbanSoccer Orsay | C24: canceled | D24: ChIJpZIJg7J45kcRrKWKhtbfnEQ | E24: 48.70829&2.17794 | F24: 2023-12-16T10:00:00.000Z
A25: 02u5zUYR9AcOED2YnEYT | B25: Cr√©teil Pompadour | C25: published | D25: ChIJX79lm6d05kcRdvnIvrrCKDc | E25: 48.771485&2.4353447 | F25: 2024-01-21T12:00:00.000Z
A26: 03Alcz66wSkAUuELRV7P | B26: STADE PIERRE BOURDAN | C26: played | D26: ChIJlzXk7HLr9EcR8P0J9oTn_Pk | E26: 45.79243109999999&4.840371699999999 | F26: 2023-10-01T08:00:00.000Z
A27: 03DtLtqnJ2ZNo2pk6TTK | B27: UrbanSoccer La D√©fense | C27: played | D27: ChIJh4rnfVhk5kcRV2Q-ZKdm8vA | E27: 48.8996456&2.2216773 | F27: 2023-11-19T18:00:00.000Z
A28: 03QkqZQKOCy1BQmtdDwH | B28: Stadium Thiais | C28: played | E28: 48.7511024&2.3713455 | F28: 2023-09-05T17:30:00.000Z
A29: 03RR9bdwDPRyQ33rcYFw | B29: UrbanSoccer - Quai d'Ivry | C29: played | D29: ChIJfXxYJ0xy5kcRw9xTkF6-FZQ | E29: 48.8199815&2.3936307 | F29: 2023-11-19T19:15:00.000Z
A30: 03U0BusYBA2ehxFNqCat | B30: LE FIVE Cr√©teil | C30: published | E30: 48.7643086&2.4706522 | F30: 2024-03-04T16:00:00.000Z
A31: 040MLBU2bXcWnGINBKVl | B31: LE FIVE Marville - La Courneuve | C31: canceled | D31: ChIJ2dHdMZxr5kcR0aKYHYsp0pY | E31: 48.9364404&2.3869147 | F31: 2023-11-09T17:30:00.000Z
A32: 04L33X6SUHv6nWtJ0mku | B32: Le 13 - Foot en salle - Marseille | C32: canceled | D32: ChIJR62kUm_ByRIRDnGQqGCeUVQ | E32: 43.33370070000001&5.370389599999999 | F32: 2023-11-21T19:00:00.000Z
A33: 04PEEV3iRE8sTvk6gCts | B33: Stadium Thiais | C33: published | E33: 48.7511024&2.3713455 | F33: 2023-09-04T17:00:00.000Z
A34: 04gJdGYyVUukYA8MRdXI | B34: Stadium Thiais | C34: played | D34: ChIJ64X9jzx05kcRsHvSfOv6UcA | E34: 48.7511024&2.3713455 | F34: 2024-01-24T18:00:00.000Z
A35: 050PGY1dw4L8S9C2Ao3l | B35: Abd Drive | C35: played | D35: ChIJCVBWxGht5kcRclC3u2EvPKs | E35: 48.86598919999999&2.4308229 | F35: 2023-10-07T07:00:00.000Z
A36: 05HbahbEePLpDe7VbADa | B36: Top Ten | C36: published | E36: 48.8729106&2.6840919 | F36: 2023-10-13T10:00:00.000Z
A37: 05JgYAaYkVgfSGckt9yo | B37: UrbanSoccer - Puteaux | C37: draft | E37: 48.8836397&2.2312283
A38: 05QHO5TE7IcXtfooRPjI | B38: Top Ten | C38: published | D38: ChIJfXprBx4b5kcRmhe-5pLZUek | E38: 48.8729106&2.6840919 | F38: 2023-10-16T16:30:00.000Z
A39: 05RXibHd2A01CjfuXl6P | B39: Stade Makowski | C39: played | D39: ChIJvShnxJpt5kcRwdqlaq1s3E0 | E39: 48.9090365&2.436058 | F39: 2023-10-08T08:00:00.000Z
A40: 05jTyZfZ3VcOTC3urnmw | B40: LE FIVE Bezons | C40: played | D40: ChIJ71Mv0Wpk5kcRg-H9x7L-dXo | E40: 48.9190419&2.2117725 | F40: 2023-10-30T18:30:00.000Z
...

Sheet Sheet1
A1: DOC_ID | B1: CENTRE | C1: STATUS | D1: PLACE_ID | E1: LOCATION | F1: DATE
A2: 00D0EPKylfi3bz0wt7ZI | B2: Game 13 foot indoor | C2: canceled | D2: ChIJNSDvlsXryRIRUXao9hwB79I | E2: 43.41258939999999&5.366617 | F2: 2023-10-16T18:30:00.000Z
A3: 00HTbiPPxn91ynn7qR1L | B3: UrbanSoccer - Porte d'Aubervilliers | C3: played | D3: ChIJ0dXjDCZs5kcRvX0EpMwxsUY | E3: 48.9074912&2.3746518 | F3: 2024-01-07T10:00:00.000Z
A4: 00LrLdN1UmDSaFH0PwoM | B4: We Are Sports | C4: canceled | D4: ChIJFZU5oBHC9EcRJTFrSkI1xxg | E4: 45.7113247&4.8761886 | F4: 2023-10-29T09:00:00.000Z
A5: 00NjDYA0rVMKo7x0Z4iR | B5: Footbox | C5: published | D5: ChIJY-WkusIR5kcR-tEad3UtaSQ | E5: 48.9022789&2.582647 | F5: 2024-01-07T17:00:00.000Z
A6: 00zKqorbhZeaIg0UDJDF | B6: Le 13 - Foot en salle - Marseille | C6: canceled | D6: ChIJR62kUm_ByRIRDnGQqGCeUVQ | E6: 43.33370070000001&5.370389599999999 | F6: 2024-01-23T22:15:00.000Z
A7: 01DNdi3KlujTX6skrg3g | B7: Game 13 foot indoor | C7: played | D7: ChIJNSDvlsXryRIRUXao9hwB79I | E7: 43.41258939999999&5.366617 | F7: 2024-01-23T20:30:00.000Z
A8: 01QB6kfRmLf35vYRDrOE | B8: Stade de foot Pompadour | C8: published | D8: ChIJZWcRAWN15kcR0aRSqeWgmaI | E8: 48.773015&2.432866 | F8: 2024-01-06T11:00:00.000Z
A9: 01ZbJa9fM9COMXnLynCM | B9: LE FIVE Paris 18 | C9: played | D9: ChIJpVT4_n1u5kcRzji6FdTBXXo | E9: 48.8978522&2.3700234 | F9: 2024-01-10T17:30:00.000Z
A10: 02VDY3BeIYvvYul4Tl3O | B10: UrbanSoccer - Puteaux | C10: played | D10: ChIJM_sC0-Nk5kcRhL1y_EFIje8 | E10: 48.8836397&2.2312283 | F10: 2023-11-04T12:30:00.000Z
A11: 02h87XMAB9N8Lny6HT0I | B11: UrbanSoccer - Puteaux | C11: canceled | D11: ChIJM_sC0-Nk5kcRhL1y_EFIje8 | E11: 48.8836397&2.2312283 | F11: 2023-10-20T17:15:00.000Z
A12: 02oe8khjbfJUb1QNXSTN | B12: UrbanSoccer Orsay | C12: canceled | D12: ChIJpZIJg7J45kcRrKWKhtbfnEQ | E12: 48.70829&2.17794 | F12: 2023-12-16T10:00:00.000Z
... A40: 09buiinuJzAiNugUEFfk | B40: Stadium Thiais | C40: played | D40: ChIJ64X9jzx05kcRsHvSfOv6UcA | E40: 48.7511024&2.3713455 | F40: 2023-10-29T15:00:00.000Z
A41: 09z2TWhR8MwcrFFNCzkq | B41: Parc Interd√©partemental des Sports du Tremblay | C41: published | D41: ChIJBVkfrQ4N5kcRGi-XnNQN_yo | E41: 48.8281085&2.491365
A42: 09znPFTdPKiYDRfZQlbZ | B42: Ball In d'Or Dreux | C42: published | D42: ChIJgRwhLzZV4UcRZ1kZ41ivPqU | E42: 48.7468231&1.3611978 | F42: 2023-12-29T18:00:00.000Z
A43: 0AFD2rDgs6RoMIGGOU4g | B43: LE FIVE Paris 18 | C43: played | D43: ChIJpVT4_n1u5kcRzji6FdTBXXo | E43: 48.8978522&2.3700234 | F43: 2024-01-06T20:30:00.000Z
A44: 0ANs9z7tdkUoHd6RoFVc | B44: Foot POWER 5 | C44: canceled | D44: ChIJuTCIFshm5kcRBtEQJ76dAzc | E44: 48.960066&2.2061913 | F44: 2023-12-09T22:30:00.000Z
A45: 0AQ3iN0JOz5fy9FTYvhr | B45: UrbanSoccer - Quai d'Ivry | C45: played | D45: ChIJfXxYJ0xy5kcRw9xTkF6-FZQ | E45: 48.8199815&2.3936307 | F45: 2023-09-25T17:00:00.000Z
A46: 0AlfRmgBwrrU56BV7Z04 | B46: UrbanSoccer - Puteaux | C46: played | D46: ChIJM_sC0-Nk5kcRhL1y_EFIje8 | E46: 48.8836397&2.2312283 | F46: 2023-11-08T21:00:00.000Z
A47: 0AnhF8k3fC8lgOxonR9g | B47: LE FIVE Paris 18 | C47: canceled | D47: ChIJpVT4_n1u5kcRzji6FdTBXXo | E47: 48.8978522&2.3700234 | F47: 2023-12-09T12:15:00.000Z
A48: 0B2hLkdnbdZy3U35zWKo | B48: Stade Pierre Letessier | C48: published | D48: ChIJmcO_CLgS5kcR_tYXn2vhXNs | E48: 48.8750074&2.4964236 | F48: 2023-12-31T09:45:00.000Z
A49: 0B8TCWpjV8qGHnCbPERr | B49: UrbanSoccer La D√©fense | C49: played | D49: ChIJh4rnfVhk5kcRV2Q-ZKdm8vA | E49: 48.8996456&2.2216773 | F49: 2023-11-01T17:45:00.000Z
A50: 0BKavgzC7CFMj4wPjjoU | B50: Top Ten | C50: played | D50: ChIJfXprBx4b5kcRmhe-5pLZUek | E50: 48.8729106&2.6840919 | F50: 2023-10-09T15:00:00.000Z
A51: 0CAvOPZHnr0dtiKnLt2R | B51: Parc Interd√©partemental des Sports du Tremblay | C51: canceled | D51: ChIJBVkfrQ4N5kcRGi-XnNQN_yo | E51: 48.8281085&2.491365 | F51: 2023-11-18T15:30:00.000Z
A52: 0CB33Z4jnM9nlDp0oAoI | B52: Stade Parfait Lebourg | C52: canceled | D52: ChIJXdP-tHUK5kcRzMpBMEOwKU8 | E52: 48.69499829999999&2.5092223 | F52: 2023-10-25T18:15:00.000Z
A53: 0CZJzbvNMjahumY1U3ad | B53: Evolution Football | C53: played | D53: ChIJX0YulIi8yRIRnGh62u3UXTQ | E53: 43.2836074&5.52356 | F53: 2023-09-26T17:30:00.000Z
... A123: 0SWOAQcuTuZgvPrU7i0Q | B123: Terre 2 Foot | C123: published | D123: ChIJK9S0wlOj4EcRx17lcyjFr0c | E123: 49.9048022&1.1127586 | F123: 2023-12-02T19:00:00.000Z
A124: 0SWhr7lMTMnqXi6X6hHq | B124: LE FIVE Paris 18 | C124: published | D124: ChIJpVT4_n1u5kcRzji6FdTBXXo | E124: 48.8978522&2.3700234
A125: 0SdIsxxRS9znubcVvlJi | B125: Play Soccer | C125: canceled | D125: ChIJQ-UxZn-5rhIRKWoQydM5T9s | E125: 43.5512023&1.4098927 | F125: 2024-01-09T16:30:00.000Z
A126: 0SmuLKeW8AcB6YbWCJyt | B126: UrbanSoccer La D√©fense | C126: canceled | D126: ChIJh4rnfVhk5kcRV2Q-ZKdm8vA | E126: 48.8996456&2.2216773 | F126: 2023-11-20T19:15:00.000Z
A127: 0SzI6KX7dqouPz656z0V | B127: LE FIVE Paris 18 | C127: canceled | D127: ChIJpVT4_n1u5kcRzji6FdTBXXo | E127: 48.8978522&2.3700234 | F127: 2023-11-26T19:00:00.000Z
A128: 0T2kdAuJo018LI3ai2s6 | B128: UrbanSoccer - Toulouse Montaudran | C128: canceled | D128: ChIJl772e0u8rhIR2foRX4Xa2CI | E128: 43.574642&1.4801835 | F128: 2023-11-13T21:00:00.000Z
A129: 0T93uMSer5Ein2jelq8r | B129: Urban Football Meudon | C129: canceled | D129: ChIJFeLBC2N75kcRyM1mlEZ3HjM | E129: 48.7983594&2.2102561 | F129: 2023-11-22T19:30:00.000Z
A130: 0TDWkUqLZxfzL5x2V2aS | B130: UrbanSoccer - Quai d'Ivry | C130: played | D130: ChIJfXxYJ0xy5kcRw9xTkF6-FZQ | E130: 48.8199815&2.3936307 | F130: 2023-11-08T16:15:00.000Z
A131: 0TENzMGiBauBulW0Hk9O | B131: Stadium Thiais | C131: canceled | D131: ChIJ64X9jzx05kcRsHvSfOv6UcA | E131: 48.7511024&2.3713455 | F131: 2023-09-23T10:30:00.000Z
A132: 0TLf0NvUvOfnqV34xMY1 | B132: UrbanSoccer - Puteaux | C132: canceled | D132: ChIJM_sC0-Nk5kcRhL1y_EFIje8 | E132: 48.8836397&2.2312283 | F132: 2024-01-15T18:30:00.000Z
A133: 0TOwJ8wVrwGLOP7j8VI2 | B133: LE FIVE Montreuil | C133: played | D133: ChIJJdTQjr0T5kcRZmGxtIJVy44 | E133: 48.8607303&2.4650432 | F133: 2024-01-18T21:00:00.000Z
A134: 0TjsldOGOcpoZcnpIVOZ | B134: Top Ten | C134: canceled | D134: ChIJfXprBx4b5kcRmhe-5pLZUek | E134: 48.8729106&2.6840919 | F134: 2023-12-22T18:00:00.000Z
A135: 0Tt2LUD4ZEHSZ6eiq4MZ | B135: LE FIVE Paris 13 | C135: played | D135: ChIJ_bOSChhz5kcRZMTeq_6Gdzg | E135: 48.8181615&2.3658793 | F135: 2023-11-15T17:00:00.000Z
A136: 0UAf4LmDrxu0dLtYA2BG | B136: LE FIVE Paris 13 | C136: published | D136: ChIJ_bOSChhz5kcRZMTeq_6Gdzg | E136: 48.8181615&2.3658793 | F136: 2023-12-04T19:00:00.000Z
...

Sheet Played+PlaceIds
A1: DOC_ID | B1: CENTRE | C1: STATUS | D1: PLACE_ID | E1: LOCATION | F1: DATE
A2: 00HTbiPPxn91ynn7qR1L | B2: UrbanSoccer - Porte d'Aubervilliers | C2: played | D2: ChIJ0dXjDCZs5kcRvX0EpMwxsUY | E2: 48.9074912&2.3746518 | F2: 2024-01-07T10:00:00.000Z
A3: 01DNdi3KlujTX6skrg3g | B3: Game 13 foot indoor | C3: played | D3: ChIJNSDvlsXryRIRUXao9hwB79I | E3: 43.41258939999999&5.366617 | F3: 2024-01-23T20:30:00.000Z
A4: 01ZbJa9fM9COMXnLynCM | B4: LE FIVE Paris 18 | C4: played | D4: ChIJpVT4_n1u5kcRzji6FdTBXXo | E4: 48.8978522&2.3700234 | F4: 2024-01-10T17:30:00.000Z
A5: 02VDY3BeIYvvYul4Tl3O | B5: UrbanSoccer - Puteaux | C5: played | D5: ChIJM_sC0-Nk5kcRhL1y_EFIje8 | E5: 48.8836397&2.2312283 | F5: 2023-11-04T12:30:00.000Z
A6: 03Alcz66wSkAUuELRV7P | B6: STADE PIERRE BOURDAN | C6: played | D6: ChIJlzXk7HLr9EcR8P0J9oTn_Pk | E6: 45.79243109999999&4.840371699999999 | F6: 2023-10-01T08:00:00.000Z
A7: 03DtLtqnJ2ZNo2pk6TTK | B7: UrbanSoccer La D√©fense | C7: played | D7: ChIJh4rnfVhk5kcRV2Q-ZKdm8vA | E7: 48.8996456&2.2216773 | F7: 2023-11-19T18:00:00.000Z
A8: 03RR9bdwDPRyQ33rcYFw | B8: UrbanSoccer - Quai d'Ivry | C8: played | D8: ChIJfXxYJ0xy5kcRw9xTkF6-FZQ | E8: 48.8199815&2.3936307 | F8: 2023-11-19T19:15:00.000Z
A9: 04gJdGYyVUukYA8MRdXI | B9: Stadium Thiais | C9: played | D9: ChIJ64X9jzx05kcRsHvSfOv6UcA | E9: 48.7511024&2.3713455 | F9: 2024-01-24T18:00:00.000Z
A10: 050PGY1dw4L8S9C2Ao3l | B10: Abd Drive | C10: played | D10: ChIJCVBWxGht5kcRclC3u2EvPKs | E10: 48.86598919999999&2.4308229 | F10: 2023-10-07T07:00:00.000Z
A11: 05RXibHd2A01CjfuXl6P | B11: Stade Makowski | C11: played | D11: ChIJvShnxJpt5kcRwdqlaq1s3E0 | E11: 48.9090365&2.436058 | F11: 2023-10-08T08:00:00.000Z
A12: 05jTyZfZ3VcOTC3urnmw | B12: LE FIVE Bezons | C12: played | D12: ChIJ71Mv0Wpk5kcRg-H9x7L-dXo | E12: 48.9190419&2.2117725 | F12: 2023-10-30T18:30:00.000Z
... A1854: Erv0PikZp7BTH3UMbITe | B1854: Stadium Thiais | C1854: played | D1854: ChIJ64X9jzx05kcRsHvSfOv6UcA | E1854: 48.7511024&2.3713455 | F1854: 2023-12-15T16:00:00.000Z
A1855: EsBcnbkRCuYGZZXMQzaT | B1855: Stade de la Tour aux Parachutes | C1855: played | D1855: ChIJbwsrhCpy5kcRca22Pnhr8MU | E1855: 48.8175176&2.3643354
A1856: EstRQJIdRgnOKXlFQc9W | B1856: LE PARK Complexe Multisports | C1856: played | D1856: ChIJdUHbID8O5kcRV5lQhiHTvhs | E1856: 48.8337843&2.5728501 | F1856: 2023-12-21T20:30:00.000Z
A1857: EvFn11KDyfTI6OUCHJac | B1857: UrbanSoccer Evry | C1857: played | D1857: ChIJW0Ut1G7e5UcRt621n2fRQ5M | E1857: 48.6286849&2.4066366 | F1857: 2023-09-29T20:15:00.000Z
A1858: EvN1UvCwgTQ0EJZoqggl | B1858: BIG5 | C1858: played | D1858: ChIJsb_7TJFp5kcRSPL5VqZulr4 | E1858: 48.9901429&2.3617895 | F1858: 2024-01-03T17:45:00.000Z
A1859: Ew6yNRPqt8OGVErtzE2C | B1859: Le 13 - Foot en salle - Marseille | C1859: played | D1859: ChIJR62kUm_ByRIRDnGQqGCeUVQ | E1859: 43.33370070000001&5.370389599999999 | F1859: 2023-12-28T19:30:00.000Z
A1860: EwToE66U3lotnxejlcDh | B1860: Evolution Football | C1860: played | D1860: ChIJX0YulIi8yRIRnGh62u3UXTQ | E1860: 43.2836074&5.52356 | F1860: 2023-11-22T18:30:00.000Z
A1861: EwaJr0iOq3zCY4C5JIJm | B1861: Gymnase Jean Blot | C1861: played | D1861: ChIJ4d5-96Nl5kcR8yiXJFyJ8Ec | E1861: 48.903562&2.253597 | F1861: 2023-10-16T18:15:00.000Z
A1862: ExJja1VIDXySto8gjuIN | B1862: Stade de l'ƒ∞le de Puteaux | C1862: played | D1862: ChIJIZUd2yJl5kcRRWoJNnmY1Ds | E1862: 48.8758697&2.2435162 | F1862: 2023-10-08T12:30:00.000Z
A1863: EyJkEKjNqfGPZg6knIUu | B1863: LE FIVE Paris 18 | C1863: played | D1863: ChIJpVT4_n1u5kcRzji6FdTBXXo | E1863: 48.8978522&2.3700234 | F1863: 2023-12-23T12:30:00.000Z
A1864: EzgmLpQWiX6ERtTVpo58 | B1864: LE FIVE Sarcelles | C1864: played | D1864: ChIJ6_q3Fxhq5kcRCpoEwnoXX1Q | E1864: 48.99782219999999&2.3902225 | F1864: 2023-12-14T19:00:00.000Z
A1865: F0cNsePOURe7LUraLmzV | B1865: OHSPORT | C1865: played | D1865: ChIJHeG9fA4X5kcRbGNzVY5Ud5I | E1865: 48.9672396&2.5670436 | F1865: 2023-10-05T19:30:00.000Z
A1866: F0kpxKyK7KawX2y4UmEv | B1866: LE FIVE Paris 18 | C1866: played | D1866: ChIJpVT4_n1u5kcRzji6FdTBXXo | E1866: 48.8978522&2.3700234 | F1866: 2023-11-10T20:00:00.000Z
A1867: F0lST0KMTuvvOVn9kzLY | B1867: Gabriel P√©ri | C1867: played | D1867: ChIJRyApR2hv5kcR1FpdLQqqHyg | E1867: 48.9162635&2.2949275 | F1867: 2023-11-12T12:10:00.000Z
... A7420: zzJEDJqFKrB6BFYNngz8 | B7420: LE FIVE Paris 18 | C7420: played | D7420: ChIJpVT4_n1u5kcRzji6FdTBXXo | E7420: 48.8978522&2.3700234 | F7420: 2023-11-19T16:30:00.000Z

Sheet Sheet2
A1: centre_name | B1: centre_place_id | C1: centre_location | D1: -
A2: Élite 5 Soccer | B2: ChIJ5-jfdlZk5kcRYIaELgvikaM | C2: =INDEX('Played+PlaceIds'!E:E,MATCH(Sheet2!B2,'Played+PlaceIds'!D:D,0)) -> 48.9009153&2.2297275 | D2: =INDEX([1]cached_centres_240126_1631!$A:$A,MATCH(B2,[1]cached_centres_240126_1631!$C:$C,0)) -> rG59DRo1lewFUT8haF7G
A3: Épidémie | B3: ChIJ01SvstEow0cREjfBiAigUhY | C3: =INDEX('Played+PlaceIds'!E:E,MATCH(Sheet2!B3,'Played+PlaceIds'!D:D,0)) -> 50.7118064&3.1661849 | D3: =INDEX([1]cached_centres_240126_1631!$A:$A,MATCH(B3,[1]cached_centres_240126_1631!$C:$C,0)) -> #N/A
A4: Abd Drive | B4: ChIJCVBWxGht5kcRclC3u2EvPKs | C4: =INDEX('Played+PlaceIds'!E:E,MATCH(Sheet2!B4,'Played+PlaceIds'!D:D,0)) -> 48.86598919999999&2.4308229 | D4: =INDEX([1]cached_centres_240126_1631!$A:$A,MATCH(B4,[1]cached_centres_240126_1631!$C:$C,0)) -> #N/A
A5: Antony | B5: ChIJf8cFRhF35kcR0D6LaMOCCwQ | C5: =INDEX('Played+PlaceIds'!E:E,MATCH(Sheet2!B5,'Played+PlaceIds'!D:D,0)) -> 48.759255&2.302553 | D5: =INDEX([1]cached_centres_240126_1631!$A:$A,MATCH(B5,[1]cached_centres_240126_1631!$C:$C,0)) -> #N/A
A6: Arena Club | B6: ChIJeWJWRjYvw0cRbnJR4ZXAKMA | C6: =INDEX('Played+PlaceIds'!E:E,MATCH(Sheet2!B6,'Played+PlaceIds'!D:D,0)) -> 50.7696017&3.1236104 | D6: =INDEX([1]cached_centres_240126_1631!$A:$A,MATCH(B6,[1]cached_centres_240126_1631!$C:$C,0)) -> #N/A
A7: B14 - Sports et Loisirs Indoor | B7: ChIJaeLKMYXe5UcRHyWJ8X8FaPA | C7: =INDEX('Played+PlaceIds'!E:E,MATCH(Sheet2!B7,'Played+PlaceIds'!D:D,0)) -> 48.62229&2.3800445 | D7: =INDEX([1]cached_centres_240126_1631!$A:$A,MATCH(B7,[1]cached_centres_240126_1631!$C:$C,0)) -> #N/A
A8: BIG5 | B8: ChIJsb_7TJFp5kcRSPL5VqZulr4 | C8: =INDEX('Played+PlaceIds'!E:E,MATCH(Sheet2!B8,'Played+PlaceIds'!D:D,0)) -> 48.9901429&2.3617895 | D8: =INDEX([1]cached_centres_240126_1631!$A:$A,MATCH(B8,[1]cached_centres_240126_1631!$C:$C,0)) -> #N/A
A9: Cap Loisirs | B9: ChIJ6xl7EP2irhIRG2TbDQazLzE | C9: =INDEX('Played+PlaceIds'!E:E,MATCH(Sheet2!B9,'Played+PlaceIds'!D:D,0)) -> 43.64393279999999&1.4791113 | D9: =INDEX([1]cached_centres_240126_1631!$A:$A,MATCH(B9,[1]cached_centres_240126_1631!$C:$C,0)) -> #N/A
A10: Classico Foot | B10: ChIJFV442oCxrhIRgsZy5aIbkNs | C10: =INDEX('Played+PlaceIds'!E:E,MATCH(Sheet2!B10,'Played+PlaceIds'!D:D,0)) -> 43.5945434&1.2911399 | D10: =INDEX([1]cached_centres_240126_1631!$A:$A,MATCH(B10,[1]cached_centres_240126_1631!$C:$C,0)) -> #N/A
A11: Events Five | B11: ChIJf8cSCJG5rhIRoQadPH-wW1U | C11: =INDEX('Played+PlaceIds'!E:E,MATCH(Sheet2!B11,'Played+PlaceIds'!D:D,0)) -> 43.5399703&1.3922897 | D11: =INDEX([1]cached_centres_240126_1631!$A:$A,MATCH(B11,[1]cached_centres_240126_1631!$C:$C,0)) -> #N/A
A12: Evolution Football | B12: ChIJX0YulIi8yRIRnGh62u3UXTQ | C12: =INDEX('Played+PlaceIds'!E:E,MATCH(Sheet2!B12,'Played+PlaceIds'!D:D,0)) -> 43.2836074&5.52356 | D12: =INDEX([1]cached_centres_240126_1631!$A:$A,MATCH(B12,[1]cached_centres_240126_1631!$C:$C,0)) -> #N/A
A13: F5 Foot Five | B13: ChIJjUbM5G7A9EcRW3mlkrhyXxY | C13: =INDEX('Played+PlaceIds'!E:E,MATCH(Sheet2!B13,'Played+PlaceIds'!D:D,0)) -> 45.7857911&4.905926399999999 | D13: =INDEX([1]cached_centres_240126_1631!$A:$A,MATCH(B13,[1]cached_centres_240126_1631!$C:$C,0)) -> #N/A
... A100: Z5 Aix | B100: ChIJKb-U_9KSyRIRKIFKbH5mW18 | C100: =INDEX('Played+PlaceIds'!E:E,MATCH(Sheet2!B100,'Played+PlaceIds'!D:D,0)) -> 43.4787869&5.3969048 | D100: =INDEX([1]cached_centres_240126_1631!$A:$A,MATCH(B100,[1]cached_centres_240126_1631!$C:$C,0)) -> #N/A
